WARNING -> 2018-12-17 16:00:07,119: build() takes at most 2 positional arguments (3 given)
WARNING -> 2018-12-17 16:00:07,123: file_cache is unavailable when using oauth2client >= 4.0.0 or google-auth
Traceback (most recent call last):
  File "C:\Anaconda3\lib\site-packages\googleapiclient\discovery_cache\__init__.py", line 36, in autodetect
    from google.appengine.api import memcache
ModuleNotFoundError: No module named 'google.appengine'

During handling of the above exception, another exception occurred:

Traceback (most recent call last):
  File "C:\Anaconda3\lib\site-packages\googleapiclient\discovery_cache\file_cache.py", line 33, in <module>
    from oauth2client.contrib.locked_file import LockedFile
ModuleNotFoundError: No module named 'oauth2client.contrib.locked_file'

During handling of the above exception, another exception occurred:

Traceback (most recent call last):
  File "C:\Anaconda3\lib\site-packages\googleapiclient\discovery_cache\file_cache.py", line 37, in <module>
    from oauth2client.locked_file import LockedFile
ModuleNotFoundError: No module named 'oauth2client.locked_file'

During handling of the above exception, another exception occurred:

Traceback (most recent call last):
  File "C:\Anaconda3\lib\site-packages\googleapiclient\discovery_cache\__init__.py", line 41, in autodetect
    from . import file_cache
  File "C:\Anaconda3\lib\site-packages\googleapiclient\discovery_cache\file_cache.py", line 41, in <module>
    'file_cache is unavailable when using oauth2client >= 4.0.0 or google-auth')
ImportError: file_cache is unavailable when using oauth2client >= 4.0.0 or google-auth
INFO -> 2018-12-17 16:00:07,125: URL being requested: GET https://www.googleapis.com/discovery/v1/apis/drive/v3/rest
WARNING -> 2018-12-17 16:00:07,406: media_mime_type argument not specified: trying to auto-detect for C:\Users\vishwas.m\Desktop\ESI.xml
INFO -> 2018-12-17 16:00:07,408: URL being requested: POST https://www.googleapis.com/upload/drive/v3/files?alt=json&uploadType=multipart
INFO -> 2018-12-17 16:00:09,213: esi
INFO -> 2018-12-17 16:01:50,540: goodbye ('127.0.0.1', 56812)
INFO -> 2018-12-17 16:01:50,541: listener closed
INFO -> 2018-12-17 16:01:50,541: server has terminated
WARNING -> 2018-12-17 16:01:51,967: build() takes at most 2 positional arguments (3 given)
WARNING -> 2018-12-17 16:01:51,971: file_cache is unavailable when using oauth2client >= 4.0.0 or google-auth
Traceback (most recent call last):
  File "C:\Anaconda3\lib\site-packages\googleapiclient\discovery_cache\__init__.py", line 36, in autodetect
    from google.appengine.api import memcache
ModuleNotFoundError: No module named 'google.appengine'

During handling of the above exception, another exception occurred:

Traceback (most recent call last):
  File "C:\Anaconda3\lib\site-packages\googleapiclient\discovery_cache\file_cache.py", line 33, in <module>
    from oauth2client.contrib.locked_file import LockedFile
ModuleNotFoundError: No module named 'oauth2client.contrib.locked_file'

During handling of the above exception, another exception occurred:

Traceback (most recent call last):
  File "C:\Anaconda3\lib\site-packages\googleapiclient\discovery_cache\file_cache.py", line 37, in <module>
    from oauth2client.locked_file import LockedFile
ModuleNotFoundError: No module named 'oauth2client.locked_file'

During handling of the above exception, another exception occurred:

Traceback (most recent call last):
  File "C:\Anaconda3\lib\site-packages\googleapiclient\discovery_cache\__init__.py", line 41, in autodetect
    from . import file_cache
  File "C:\Anaconda3\lib\site-packages\googleapiclient\discovery_cache\file_cache.py", line 41, in <module>
    'file_cache is unavailable when using oauth2client >= 4.0.0 or google-auth')
ImportError: file_cache is unavailable when using oauth2client >= 4.0.0 or google-auth
INFO -> 2018-12-17 16:01:51,973: URL being requested: GET https://www.googleapis.com/discovery/v1/apis/drive/v3/rest
WARNING -> 2018-12-17 16:01:52,132: media_mime_type argument not specified: trying to auto-detect for C:\Users\vishwas.m\Desktop\ESI.xml
INFO -> 2018-12-17 16:01:52,134: URL being requested: POST https://www.googleapis.com/upload/drive/v3/files?alt=json&uploadType=multipart
INFO -> 2018-12-17 16:01:53,908: esi
INFO -> 2018-12-17 16:05:16,271: goodbye ('127.0.0.1', 56863)
INFO -> 2018-12-17 16:05:16,272: listener closed
INFO -> 2018-12-17 16:05:16,273: server has terminated
